<?xml version="1.0" encoding="utf-8"?>
<!-- This URDF was automatically created by SolidWorks to URDF Exporter! Originally created by Stephen Brawner (brawner@gmail.com) 
     Commit Version: 1.5.1-0-g916b5db  Build Version: 1.5.7152.31018
     For more information, please see http://wiki.ros.org/sw_urdf_exporter -->
<robot
  name="pixle_godzilla">
  <link
    name="base_link">
    <inertial>
      <origin
        xyz="-8.16730634702638E-05 0.13984285173906 -0.0153390282843539"
        rpy="0 0 1.5708" />
      <mass
        value="92.5579966055029" />
      <inertia
        ixx="3.18294943092091"
        ixy="0.00118919543838747"
        ixz="0.000342820576389713"
        iyy="4.92429108625664"
        iyz="0.165207356728358"
        izz="3.12655627149977" />
    </inertial>
    <visual>
      <origin
        xyz="0 0 0"
        rpy="0 0 1.5708" />
      <geometry>
        <mesh
          filename="package://pixle_godzilla/meshes/base_link.STL" />
      </geometry>
      <material
        name="">
        <color
          rgba="1 1 1 1" />
      </material>
    </visual>
    <collision>
      <origin
        xyz="0 0 0"
        rpy="0 0 1.5708" />
      <geometry>
        <mesh
          filename="package://pixle_godzilla/meshes/base_link.STL" />
      </geometry>
    </collision>
  </link>
  <link
    name="shoulder">
    <inertial>
      <origin
        xyz="0 0.0796968098192792 1.38777878078145E-17"
        rpy="0 0 0" />
      <mass
        value="3.65972330316483" />
      <inertia
        ixx="0.0187688423989809"
        ixy="4.2351647362715E-19"
        ixz="1.27375243231002E-10"
        iyy="0.0239400432221818"
        iyz="-1.21679856967423E-18"
        izz="0.0265455743803694" />
    </inertial>
    <visual>
      <origin
        xyz="0 0 0"
        rpy="0 0 0" />
      <geometry>
        <mesh
          filename="package://pixle_godzilla/meshes/shoulder.STL" />
      </geometry>
      <material
        name="">
        <color
          rgba="1 1 1 1" />
      </material>
    </visual>
    <collision>
      <origin
        xyz="0 0 0"
        rpy="0 0 0" />
      <geometry>
        <mesh
          filename="package://pixle_godzilla/meshes/shoulder.STL" />
      </geometry>
    </collision>
  </link>
  <joint
    name="shoulder"
    type="revolute">
    <origin
      xyz="0.09425 0 0.2925"
      rpy="1.5708 0 1.5708" />
    <parent
      link="base_link" />
    <child
      link="shoulder" />
    <axis
      xyz="0 1 0" />
    <limit
      lower="-1.5708"
      upper="4.18879"
      effort="100.0"
      velocity="40.0" />
    <safety_controller
      soft_upper_limit="4.18879"
      soft_lower_limit="-1.5708"
      k_position="100.0"
      k_velocity="80.0" />
  </joint>
  <link
    name="arm">
    <inertial>
      <origin
        xyz="-0.00442534732237772 0.0856261227947502 -1.1960985287925E-17"
        rpy="0 0 0" />
      <mass
        value="1.30424013184074" />
      <inertia
        ixx="0.00664727823178329"
        ixy="5.60569909364734E-05"
        ixz="1.07055078512681E-19"
        iyy="0.00140099636059824"
        iyz="-4.85666135848229E-19"
        izz="0.00656524534131322" />
    </inertial>
    <visual>
      <origin
        xyz="0 0 0"
        rpy="0 0 0" />
      <geometry>
        <mesh
          filename="package://pixle_godzilla/meshes/arm.STL" />
      </geometry>
      <material
        name="">
        <color
          rgba="1 1 1 1" />
      </material>
    </visual>
    <collision>
      <origin
        xyz="0 0 0"
        rpy="0 0 0" />
      <geometry>
        <mesh
          filename="package://pixle_godzilla/meshes/arm.STL" />
      </geometry>
    </collision>
  </link>
  <joint
    name="arm"
    type="revolute">
    <origin
      xyz="0 0.108 0"
      rpy="0 -1.5708 0" />
    <parent
      link="shoulder" />
    <child
      link="arm" />
    <axis
      xyz="0 0 1" />
    <limit
      lower="-2.0736"
      upper="1.1170107213"
      effort="100.0"
      velocity="40.0" />
    <safety_controller
      soft_upper_limit="1.1170107213"
      soft_lower_limit="-2.0736"
      k_position="100.0"
      k_velocity="80.0" />
  </joint>
  <link
    name="forearm">
    <inertial>
      <origin
        xyz="0.0936923463087018 3.10951717816003E-17 -0.00413431758700977"
        rpy="0 0 0" />
      <mass
        value="0.984291918362788" />
      <inertia
        ixx="0.00073510497708009"
        ixy="-1.95966583165041E-18"
        ixz="-9.05203433722015E-05"
        iyy="0.00602869610341503"
        iyz="-2.19264466748436E-20"
        izz="0.00585688135039201" />
    </inertial>
    <visual>
      <origin
        xyz="0 0 0"
        rpy="0 0 0" />
      <geometry>
        <mesh
          filename="package://pixle_godzilla/meshes/forearm.STL" />
      </geometry>
      <material
        name="">
        <color
          rgba="1 1 1 1" />
      </material>
    </visual>
    <collision>
      <origin
        xyz="0 0 0"
        rpy="0 0 0" />
      <geometry>
        <mesh
          filename="package://pixle_godzilla/meshes/forearm.STL" />
      </geometry>
    </collision>
  </link>
  <joint
    name="forearm"
    type="revolute">
    <origin
      xyz="0 0.213 0"
      rpy="1.5708 0 0" />
    <parent
      link="arm" />
    <child
      link="forearm" />
    <axis
      xyz="0 1 0" />
    <limit
      lower="-0.7679"
      upper="2.2689280276"
      effort="100.0"
      velocity="40.0" />
    <safety_controller
      soft_upper_limit="2.2689280276"
      soft_lower_limit="-0.8901179185"
      k_position="100.0"
      k_velocity="80.0" />
  </joint>
  <link
    name="roll_spindle">
    <inertial>
      <origin
        xyz="0.0144703804867855 -0.0394302540215672 -1.18932169901314E-16"
        rpy="0 0 0" />
      <mass
        value="0.126380309298372" />
      <inertia
        ixx="0.000131246756841335"
        ixy="3.59197079416034E-05"
        ixz="-3.65434048020945E-20"
        iyy="0.000392083371850193"
        iyz="1.82165674008812E-20"
        izz="0.000455982270176141" />
    </inertial>
    <visual>
      <origin
        xyz="0 0 0"
        rpy="0 0 0" />
      <geometry>
        <mesh
          filename="package://pixle_godzilla/meshes/roll_spindle.STL" />
      </geometry>
      <material
        name="">
        <color
          rgba="1 1 1 1" />
      </material>
    </visual>
    <collision>
      <origin
        xyz="0 0 0"
        rpy="0 0 0" />
      <geometry>
        <mesh
          filename="package://pixle_godzilla/meshes/roll_spindle.STL" />
      </geometry>
    </collision>
  </link>
  <joint
    name="roll_spindle"
    type="revolute">
    <origin
      xyz="0.22 0 -0.003"
      rpy="0 3.1416 1.5708" />
    <parent
      link="forearm" />
    <child
      link="roll_spindle" />
    <axis
      xyz="0 1 0" />
    <limit
      lower="-3.15"
      upper="3.15"
      effort="100.0"
      velocity="40.0" />
    <safety_controller
      soft_upper_limit="3.15"
      soft_lower_limit="-3.15"
      k_position="100.0"
      k_velocity="80.0" />
  </joint>
  <link
    name="pitch_spindle">
    <inertial>
      <origin
        xyz="0.00879862952479366 -0.0138699194515684 1.11022302462516E-16"
        rpy="0 0 0" />
      <mass
        value="0.107322328062624" />
      <inertia
        ixx="0.000203203433206688"
        ixy="5.35436366442418E-06"
        ixz="7.13210729614397E-20"
        iyy="8.69977626846247E-05"
        iyz="-4.74952483620863E-20"
        izz="0.000168233733559111" />
    </inertial>
    <visual>
      <origin
        xyz="0 0 0"
        rpy="0 0 0" />
      <geometry>
        <mesh
          filename="package://pixle_godzilla/meshes/pitch_spindle.STL" />
      </geometry>
      <material
        name="">
        <color
          rgba="1 1 1 1" />
      </material>
    </visual>
    <collision>
      <origin
        xyz="0 0 0"
        rpy="0 0 0" />
      <geometry>
        <mesh
          filename="package://pixle_godzilla/meshes/pitch_spindle.STL" />
      </geometry>
    </collision>
  </link>
  <joint
    name="pitch_spindle"
    type="revolute">
    <origin
      xyz="0 -0.07 0"
      rpy="1.5708 0 1.5708" />
    <parent
      link="roll_spindle" />
    <child
      link="pitch_spindle" />
    <axis
      xyz="0 0 1" />
    <limit
      lower="-3.1415926536"
      upper="3.1415926536"
      effort="100.0"
      velocity="40.0" />
    <safety_controller
      soft_upper_limit="3.1415926536"
      soft_lower_limit="-3.1415926536"
      k_position="100.0"
      k_velocity="80.0" />
  </joint>
  <link
    name="yaw_spindle">
    <inertial>
      <origin
        xyz="-1.11022302462516E-16 -0.028687821744227 8.9395409083665E-17"
        rpy="0 0 0" />
      <mass
        value="0.0352524228409237" />
      <inertia
        ixx="1.67234651240252E-05"
        ixy="-3.3460949508167E-22"
        ixz="-5.89488498692369E-22"
        iyy="1.10882910473656E-05"
        iyz="1.38863248007155E-21"
        izz="1.35987914275225E-05" />
    </inertial>
    <visual>
      <origin
        xyz="0 0 0"
        rpy="0 0 0" />
      <geometry>
        <mesh
          filename="package://pixle_godzilla/meshes/yaw_spindle.STL" />
      </geometry>
      <material
        name="">
        <color
          rgba="0.866666666666667 0.866666666666667 0.890196078431372 1" />
      </material>
    </visual>
    <collision>
      <origin
        xyz="0 0 0"
        rpy="0 0 0" />
      <geometry>
        <mesh
          filename="package://pixle_godzilla/meshes/yaw_spindle.STL" />
      </geometry>
    </collision>
  </link>
  <joint
    name="yaw_spindle"
    type="revolute">
    <origin
      xyz="0 0 0"
      rpy="1.5708 1.5708 0" />
    <parent
      link="pitch_spindle" />
    <child
      link="yaw_spindle" />
    <axis
      xyz="0 0 1" />
    <limit
      lower="-0.7116"
      upper="0.7116"
      effort="100.0"
      velocity="40.0" />
    <safety_controller
      soft_upper_limit="0.7116"
      soft_lower_limit="-0.7116"
      k_position="100.0"
      k_velocity="80.0" />
  </joint>
</robot>